# ✅ Issue Fixed: AttributeError in web_app_realtime.py

## 🐛 Original Error

```python
Traceback (most recent call last):
  File "/Users/henanli/dev/gtc-hackathon/web_app_realtime.py", line 130, in run_real_investigation
    'symptom': f"{technical_context.problem_category}: {technical_context.technical_description}",
AttributeError: 'TechnicalContext' object has no attribute 'problem_category'
```

## 🔍 Root Cause Analysis

The issue occurred because `web_app_realtime.py` was trying to access attributes that don't exist in the `TechnicalContext` dataclass.

### Expected Attributes (❌ Wrong)
```python
technical_context.problem_category      # Doesn't exist
technical_context.technical_description # Doesn't exist
```

### Actual Attributes (✅ Correct)
```python
@dataclass
class TechnicalContext:
    incident_id: str
    system_affected: str        # ✅ Available
    symptoms: List[str]         # ✅ Available
    urgency_level: str          # ✅ Available
    timing_info: Dict[str, str] # ✅ Available
    user_impact: str            # ✅ Available
    raw_user_input: str         # ✅ Available
```

## 🔧 The Fix

### Before (Line 130)
```python
incident = {
    'id': incident_id,
    'symptom': f"{technical_context.problem_category}: {technical_context.technical_description}",
    'severity': technical_context.urgency_level,
    'service': technical_context.system_affected,
    'impact': f"System {technical_context.system_affected} affected"
}
```

### After (Fixed)
```python
# Format symptoms as a readable string
symptoms_text = ", ".join(technical_context.symptoms) if technical_context.symptoms else "Unknown issue"

incident = {
    'id': incident_id,
    'symptom': f"{technical_context.system_affected} issue: {symptoms_text}",
    'severity': technical_context.urgency_level,
    'service': technical_context.system_affected,
    'impact': technical_context.user_impact
}
```

## ✅ Verification Test

Created `test_fix.py` to verify the fix:

```bash
$ python test_fix.py

✅ Translation successful!

Technical Context attributes:
  - system_affected: email
  - symptoms: ['functionality_broken']
  - urgency_level: high
  - user_impact: single_user

✅ Incident dict created successfully:
  - ID: TEST-001
  - Symptom: email issue: functionality_broken
  - Severity: high
  - Service: email
  - Impact: single_user

✅ All tests passed! The fix works correctly.
```

## 📊 Impact

### What Changed
- ✅ Fixed attribute access to use correct `TechnicalContext` attributes
- ✅ Improved symptom formatting (joins list of symptoms)
- ✅ Used actual `user_impact` instead of generic string
- ✅ Maintained backward compatibility

### What Didn't Change
- ✅ No changes to `TechnicalContext` dataclass
- ✅ No changes to `IncidentTranslator` logic
- ✅ No breaking changes to API

## 🚀 Next Steps

### To Use the Fixed Version
```bash
# Start the server
python web_app_realtime.py

# Or use the convenience script
./start_warroom.sh
```

### To Verify It Works
1. Navigate to `http://localhost:5000`
2. Fill out an incident report
3. Submit and watch the investigation page
4. The error should no longer occur

## 🔍 How to Debug Similar Issues

### 1. Check the Dataclass Definition
```python
# Look at the actual dataclass
from examples.nonprofit_interface import TechnicalContext
import inspect
print(inspect.signature(TechnicalContext))
```

### 2. Print Available Attributes
```python
# In your code, add debugging
print(f"Available attributes: {dir(technical_context)}")
```

### 3. Use Type Hints
```python
# Add type hints to catch issues early
def run_real_investigation(
    incident_id: str,
    technical_context: TechnicalContext  # IDE will show available attributes
) -> None:
    ...
```

## 📝 Lessons Learned

1. **Always verify dataclass attributes** before accessing them
2. **Use IDE autocomplete** to catch attribute errors early
3. **Add defensive checks** for optional or list attributes
4. **Write tests** to verify attribute access works correctly

## 🛡️ Prevention

To prevent similar issues:

### 1. Add Type Checking
```bash
# Install mypy
pip install mypy

# Run type checker
mypy web_app_realtime.py
```

### 2. Add Unit Tests
```python
def test_technical_context_attributes():
    """Verify TechnicalContext has expected attributes"""
    context = TechnicalContext(...)
    assert hasattr(context, 'system_affected')
    assert hasattr(context, 'symptoms')
    assert hasattr(context, 'urgency_level')
```

### 3. Use IDE Features
- Enable type checking in VS Code/PyCharm
- Use attribute autocomplete
- Enable inline error detection

## 📚 Related Files

- **Fixed file**: `web_app_realtime.py` (line 127-137)
- **Dataclass definition**: `examples/nonprofit_interface.py` (line 30-40)
- **Test file**: `test_fix.py` (verification)

## ✅ Status: **RESOLVED**

The issue has been fixed and tested. The server should now run without AttributeError.
